
Unhandled exception on musk_event_handler
Traceback (most recent call last):
  File "/home/ubuntu/.local/lib/python3.10/site-packages/telethon/client/updates.py", line 520, in _dispatch_update
    await callback(event)
  File "/home/ubuntu/deployment/tg/listener.py", line 34, in musk_event_handler
    analysis_musk(event.text)
  File "/home/ubuntu/deployment/tg/scraper_utils.py", line 47, in analysis_musk
    insert_musk(tweet_time, ttype, content)
  File "/home/ubuntu/deployment/tg/cmysql.py", line 47, in insert_musk
    cursor.execute(sql, (ttime, ttype, content))
  File "/home/ubuntu/.local/lib/python3.10/site-packages/pymysql/cursors.py", line 148, in execute
    result = self._query(query)
  File "/home/ubuntu/.local/lib/python3.10/site-packages/pymysql/cursors.py", line 310, in _query
    conn.query(q)
  File "/home/ubuntu/.local/lib/python3.10/site-packages/pymysql/connections.py", line 548, in query
    self._affected_rows = self._read_query_result(unbuffered=unbuffered)
  File "/home/ubuntu/.local/lib/python3.10/site-packages/pymysql/connections.py", line 775, in _read_query_result
    result.read()
  File "/home/ubuntu/.local/lib/python3.10/site-packages/pymysql/connections.py", line 1156, in read
    first_packet = self.connection._read_packet()
  File "/home/ubuntu/.local/lib/python3.10/site-packages/pymysql/connections.py", line 725, in _read_packet
    packet.raise_for_error()
  File "/home/ubuntu/.local/lib/python3.10/site-packages/pymysql/protocol.py", line 221, in raise_for_error
    err.raise_mysql_exception(self._data)
  File "/home/ubuntu/.local/lib/python3.10/site-packages/pymysql/err.py", line 143, in raise_mysql_exception
    raise errorclass(errno, errval)
pymysql.err.DataError: (1366, "Incorrect string value: '\\xF0\\x9F\\xA4\\xA3**' for column 'content' at row 1")
Unhandled exception on news_event_handler
Traceback (most recent call last):
  File "/home/ubuntu/deployment/tg/cmysql.py", line 59, in insert_news
    cursor.execute(sql, (ntime, ntype, content, url, tokens))
  File "/home/ubuntu/.local/lib/python3.10/site-packages/pymysql/cursors.py", line 148, in execute
    result = self._query(query)
  File "/home/ubuntu/.local/lib/python3.10/site-packages/pymysql/cursors.py", line 310, in _query
    conn.query(q)
  File "/home/ubuntu/.local/lib/python3.10/site-packages/pymysql/connections.py", line 547, in query
    self._execute_command(COMMAND.COM_QUERY, sql)
  File "/home/ubuntu/.local/lib/python3.10/site-packages/pymysql/connections.py", line 793, in _execute_command
    raise err.InterfaceError(0, "")
pymysql.err.InterfaceError: (0, '')

During handling of the above exception, another exception occurred:

Traceback (most recent call last):
  File "/home/ubuntu/.local/lib/python3.10/site-packages/telethon/client/updates.py", line 520, in _dispatch_update
    await callback(event)
  File "/home/ubuntu/deployment/tg/listener.py", line 40, in news_event_handler
    analysis_news(event.text)
  File "/home/ubuntu/deployment/tg/scraper_utils.py", line 83, in analysis_news
    insert_news(ntime, ntype, news_content, url, tokens)
  File "/home/ubuntu/deployment/tg/cmysql.py", line 55, in insert_news
    with connection:
  File "/home/ubuntu/.local/lib/python3.10/site-packages/pymysql/connections.py", line 360, in __exit__
    self.close()
  File "/home/ubuntu/.local/lib/python3.10/site-packages/pymysql/connections.py", line 404, in close
    raise err.Error("Already closed")
pymysql.err.Error: Already closed
Unhandled exception on news_event_handler
Traceback (most recent call last):
  File "/home/ubuntu/deployment/tg/cmysql.py", line 59, in insert_news
    cursor.execute(sql, (ntime, ntype, content, url, tokens))
  File "/home/ubuntu/.local/lib/python3.10/site-packages/pymysql/cursors.py", line 148, in execute
    result = self._query(query)
  File "/home/ubuntu/.local/lib/python3.10/site-packages/pymysql/cursors.py", line 310, in _query
    conn.query(q)
  File "/home/ubuntu/.local/lib/python3.10/site-packages/pymysql/connections.py", line 547, in query
    self._execute_command(COMMAND.COM_QUERY, sql)
  File "/home/ubuntu/.local/lib/python3.10/site-packages/pymysql/connections.py", line 793, in _execute_command
    raise err.InterfaceError(0, "")
pymysql.err.InterfaceError: (0, '')

During handling of the above exception, another exception occurred:

Traceback (most recent call last):
  File "/home/ubuntu/.local/lib/python3.10/site-packages/telethon/client/updates.py", line 520, in _dispatch_update
    await callback(event)
  File "/home/ubuntu/deployment/tg/listener.py", line 40, in news_event_handler
    analysis_news(event.text)
  File "/home/ubuntu/deployment/tg/scraper_utils.py", line 83, in analysis_news
    insert_news(ntime, ntype, news_content, url, tokens)
  File "/home/ubuntu/deployment/tg/cmysql.py", line 55, in insert_news
    with connection:
  File "/home/ubuntu/.local/lib/python3.10/site-packages/pymysql/connections.py", line 360, in __exit__
    self.close()
  File "/home/ubuntu/.local/lib/python3.10/site-packages/pymysql/connections.py", line 404, in close
    raise err.Error("Already closed")
pymysql.err.Error: Already closed
Unhandled exception on news_event_handler
Traceback (most recent call last):
  File "/home/ubuntu/deployment/tg/cmysql.py", line 59, in insert_news
    cursor.execute(sql, (ntime, ntype, content, url, tokens))
  File "/home/ubuntu/.local/lib/python3.10/site-packages/pymysql/cursors.py", line 148, in execute
    result = self._query(query)
  File "/home/ubuntu/.local/lib/python3.10/site-packages/pymysql/cursors.py", line 310, in _query
    conn.query(q)
  File "/home/ubuntu/.local/lib/python3.10/site-packages/pymysql/connections.py", line 547, in query
    self._execute_command(COMMAND.COM_QUERY, sql)
  File "/home/ubuntu/.local/lib/python3.10/site-packages/pymysql/connections.py", line 793, in _execute_command
    raise err.InterfaceError(0, "")
pymysql.err.InterfaceError: (0, '')

During handling of the above exception, another exception occurred:

Traceback (most recent call last):
  File "/home/ubuntu/.local/lib/python3.10/site-packages/telethon/client/updates.py", line 520, in _dispatch_update
    await callback(event)
  File "/home/ubuntu/deployment/tg/listener.py", line 40, in news_event_handler
    analysis_news(event.text)
  File "/home/ubuntu/deployment/tg/scraper_utils.py", line 83, in analysis_news
    insert_news(ntime, ntype, news_content, url, tokens)
  File "/home/ubuntu/deployment/tg/cmysql.py", line 55, in insert_news
    with connection:
  File "/home/ubuntu/.local/lib/python3.10/site-packages/pymysql/connections.py", line 360, in __exit__
    self.close()
  File "/home/ubuntu/.local/lib/python3.10/site-packages/pymysql/connections.py", line 404, in close
    raise err.Error("Already closed")
pymysql.err.Error: Already closed
Unhandled exception on news_event_handler
Traceback (most recent call last):
  File "/home/ubuntu/deployment/tg/cmysql.py", line 59, in insert_news
    cursor.execute(sql, (ntime, ntype, content, url, tokens))
  File "/home/ubuntu/.local/lib/python3.10/site-packages/pymysql/cursors.py", line 148, in execute
    result = self._query(query)
  File "/home/ubuntu/.local/lib/python3.10/site-packages/pymysql/cursors.py", line 310, in _query
    conn.query(q)
  File "/home/ubuntu/.local/lib/python3.10/site-packages/pymysql/connections.py", line 547, in query
    self._execute_command(COMMAND.COM_QUERY, sql)
  File "/home/ubuntu/.local/lib/python3.10/site-packages/pymysql/connections.py", line 793, in _execute_command
    raise err.InterfaceError(0, "")
pymysql.err.InterfaceError: (0, '')

During handling of the above exception, another exception occurred:

Traceback (most recent call last):
  File "/home/ubuntu/.local/lib/python3.10/site-packages/telethon/client/updates.py", line 520, in _dispatch_update
    await callback(event)
  File "/home/ubuntu/deployment/tg/listener.py", line 40, in news_event_handler
    analysis_news(event.text)
  File "/home/ubuntu/deployment/tg/scraper_utils.py", line 83, in analysis_news
    insert_news(ntime, ntype, news_content, url, tokens)
  File "/home/ubuntu/deployment/tg/cmysql.py", line 55, in insert_news
    with connection:
  File "/home/ubuntu/.local/lib/python3.10/site-packages/pymysql/connections.py", line 360, in __exit__
    self.close()
  File "/home/ubuntu/.local/lib/python3.10/site-packages/pymysql/connections.py", line 404, in close
    raise err.Error("Already closed")
pymysql.err.Error: Already closed
Unhandled exception on news_event_handler
Traceback (most recent call last):
  File "/home/ubuntu/deployment/tg/cmysql.py", line 59, in insert_news
    cursor.execute(sql, (ntime, ntype, content, url, tokens))
  File "/home/ubuntu/.local/lib/python3.10/site-packages/pymysql/cursors.py", line 148, in execute
    result = self._query(query)
  File "/home/ubuntu/.local/lib/python3.10/site-packages/pymysql/cursors.py", line 310, in _query
    conn.query(q)
  File "/home/ubuntu/.local/lib/python3.10/site-packages/pymysql/connections.py", line 547, in query
    self._execute_command(COMMAND.COM_QUERY, sql)
  File "/home/ubuntu/.local/lib/python3.10/site-packages/pymysql/connections.py", line 793, in _execute_command
    raise err.InterfaceError(0, "")
pymysql.err.InterfaceError: (0, '')

During handling of the above exception, another exception occurred:

Traceback (most recent call last):
  File "/home/ubuntu/.local/lib/python3.10/site-packages/telethon/client/updates.py", line 520, in _dispatch_update
    await callback(event)
  File "/home/ubuntu/deployment/tg/listener.py", line 40, in news_event_handler
    analysis_news(event.text)
  File "/home/ubuntu/deployment/tg/scraper_utils.py", line 83, in analysis_news
    insert_news(ntime, ntype, news_content, url, tokens)
  File "/home/ubuntu/deployment/tg/cmysql.py", line 55, in insert_news
    with connection:
  File "/home/ubuntu/.local/lib/python3.10/site-packages/pymysql/connections.py", line 360, in __exit__
    self.close()
  File "/home/ubuntu/.local/lib/python3.10/site-packages/pymysql/connections.py", line 404, in close
    raise err.Error("Already closed")
pymysql.err.Error: Already closed
Unhandled exception on news_event_handler
Traceback (most recent call last):
  File "/home/ubuntu/deployment/tg/cmysql.py", line 59, in insert_news
    cursor.execute(sql, (ntime, ntype, content, url, tokens))
  File "/home/ubuntu/.local/lib/python3.10/site-packages/pymysql/cursors.py", line 148, in execute
    result = self._query(query)
  File "/home/ubuntu/.local/lib/python3.10/site-packages/pymysql/cursors.py", line 310, in _query
    conn.query(q)
  File "/home/ubuntu/.local/lib/python3.10/site-packages/pymysql/connections.py", line 547, in query
    self._execute_command(COMMAND.COM_QUERY, sql)
  File "/home/ubuntu/.local/lib/python3.10/site-packages/pymysql/connections.py", line 793, in _execute_command
    raise err.InterfaceError(0, "")
pymysql.err.InterfaceError: (0, '')

During handling of the above exception, another exception occurred:

Traceback (most recent call last):
  File "/home/ubuntu/.local/lib/python3.10/site-packages/telethon/client/updates.py", line 520, in _dispatch_update
    await callback(event)
  File "/home/ubuntu/deployment/tg/listener.py", line 40, in news_event_handler
    analysis_news(event.text)
  File "/home/ubuntu/deployment/tg/scraper_utils.py", line 83, in analysis_news
    insert_news(ntime, ntype, news_content, url, tokens)
  File "/home/ubuntu/deployment/tg/cmysql.py", line 55, in insert_news
    with connection:
  File "/home/ubuntu/.local/lib/python3.10/site-packages/pymysql/connections.py", line 360, in __exit__
    self.close()
  File "/home/ubuntu/.local/lib/python3.10/site-packages/pymysql/connections.py", line 404, in close
    raise err.Error("Already closed")
pymysql.err.Error: Already closed
Unhandled exception on news_event_handler
Traceback (most recent call last):
  File "/home/ubuntu/deployment/tg/cmysql.py", line 59, in insert_news
    cursor.execute(sql, (ntime, ntype, content, url, tokens))
  File "/home/ubuntu/.local/lib/python3.10/site-packages/pymysql/cursors.py", line 148, in execute
    result = self._query(query)
  File "/home/ubuntu/.local/lib/python3.10/site-packages/pymysql/cursors.py", line 310, in _query
    conn.query(q)
  File "/home/ubuntu/.local/lib/python3.10/site-packages/pymysql/connections.py", line 547, in query
    self._execute_command(COMMAND.COM_QUERY, sql)
  File "/home/ubuntu/.local/lib/python3.10/site-packages/pymysql/connections.py", line 793, in _execute_command
    raise err.InterfaceError(0, "")
pymysql.err.InterfaceError: (0, '')

During handling of the above exception, another exception occurred:

Traceback (most recent call last):
  File "/home/ubuntu/.local/lib/python3.10/site-packages/telethon/client/updates.py", line 520, in _dispatch_update
    await callback(event)
  File "/home/ubuntu/deployment/tg/listener.py", line 40, in news_event_handler
    analysis_news(event.text)
  File "/home/ubuntu/deployment/tg/scraper_utils.py", line 83, in analysis_news
    insert_news(ntime, ntype, news_content, url, tokens)
  File "/home/ubuntu/deployment/tg/cmysql.py", line 55, in insert_news
    with connection:
  File "/home/ubuntu/.local/lib/python3.10/site-packages/pymysql/connections.py", line 360, in __exit__
    self.close()
  File "/home/ubuntu/.local/lib/python3.10/site-packages/pymysql/connections.py", line 404, in close
    raise err.Error("Already closed")
pymysql.err.Error: Already closed
Unhandled exception on news_event_handler
Traceback (most recent call last):
  File "/home/ubuntu/deployment/tg/cmysql.py", line 59, in insert_news
    cursor.execute(sql, (ntime, ntype, content, url, tokens))
  File "/home/ubuntu/.local/lib/python3.10/site-packages/pymysql/cursors.py", line 148, in execute
    result = self._query(query)
  File "/home/ubuntu/.local/lib/python3.10/site-packages/pymysql/cursors.py", line 310, in _query
    conn.query(q)
  File "/home/ubuntu/.local/lib/python3.10/site-packages/pymysql/connections.py", line 547, in query
    self._execute_command(COMMAND.COM_QUERY, sql)
  File "/home/ubuntu/.local/lib/python3.10/site-packages/pymysql/connections.py", line 793, in _execute_command
    raise err.InterfaceError(0, "")
pymysql.err.InterfaceError: (0, '')

During handling of the above exception, another exception occurred:

Traceback (most recent call last):
  File "/home/ubuntu/.local/lib/python3.10/site-packages/telethon/client/updates.py", line 520, in _dispatch_update
    await callback(event)
  File "/home/ubuntu/deployment/tg/listener.py", line 40, in news_event_handler
    analysis_news(event.text)
  File "/home/ubuntu/deployment/tg/scraper_utils.py", line 83, in analysis_news
    insert_news(ntime, ntype, news_content, url, tokens)
  File "/home/ubuntu/deployment/tg/cmysql.py", line 55, in insert_news
    with connection:
  File "/home/ubuntu/.local/lib/python3.10/site-packages/pymysql/connections.py", line 360, in __exit__
    self.close()
  File "/home/ubuntu/.local/lib/python3.10/site-packages/pymysql/connections.py", line 404, in close
    raise err.Error("Already closed")
pymysql.err.Error: Already closed
Unhandled exception on news_event_handler
Traceback (most recent call last):
  File "/home/ubuntu/deployment/tg/cmysql.py", line 59, in insert_news
    cursor.execute(sql, (ntime, ntype, content, url, tokens))
  File "/home/ubuntu/.local/lib/python3.10/site-packages/pymysql/cursors.py", line 148, in execute
    result = self._query(query)
  File "/home/ubuntu/.local/lib/python3.10/site-packages/pymysql/cursors.py", line 310, in _query
    conn.query(q)
  File "/home/ubuntu/.local/lib/python3.10/site-packages/pymysql/connections.py", line 547, in query
    self._execute_command(COMMAND.COM_QUERY, sql)
  File "/home/ubuntu/.local/lib/python3.10/site-packages/pymysql/connections.py", line 793, in _execute_command
    raise err.InterfaceError(0, "")
pymysql.err.InterfaceError: (0, '')

During handling of the above exception, another exception occurred:

Traceback (most recent call last):
  File "/home/ubuntu/.local/lib/python3.10/site-packages/telethon/client/updates.py", line 520, in _dispatch_update
    await callback(event)
  File "/home/ubuntu/deployment/tg/listener.py", line 40, in news_event_handler
    analysis_news(event.text)
  File "/home/ubuntu/deployment/tg/scraper_utils.py", line 83, in analysis_news
    insert_news(ntime, ntype, news_content, url, tokens)
  File "/home/ubuntu/deployment/tg/cmysql.py", line 55, in insert_news
    with connection:
  File "/home/ubuntu/.local/lib/python3.10/site-packages/pymysql/connections.py", line 360, in __exit__
    self.close()
  File "/home/ubuntu/.local/lib/python3.10/site-packages/pymysql/connections.py", line 404, in close
    raise err.Error("Already closed")
pymysql.err.Error: Already closed
